cv-parser-worker-2  |     from app.services.parser import parse_cv
cv-parser-worker-2  |   File "/app/app/services/parser.py", line 15, in <module>
cv-parser-worker-2  |     from app.services.resilience import resilient_openai_call
cv-parser-worker-2  |   File "/app/app/services/resilience.py", line 17, in <module>
cv-parser-worker-2  |     client = OpenAI(api_key=settings.OPENAI_API_KEY)
cv-parser-worker-2  |              ^^^^^^^^^^^^^^^^^^^^^^^^^^^^^^^^^^^^^^^
cv-parser-worker-2  |   File "/usr/local/lib/python3.11/site-packages/openai/_client.py", line 107, in __init__
cv-parser-worker-2  |     super().__init__(
cv-parser-worker-2  |   File "/usr/local/lib/python3.11/site-packages/openai/_base_client.py", line 738, in __init__
cv-parser-worker-2  |     self._client = http_client or httpx.Client(
cv-parser-worker-2  |                                   ^^^^^^^^^^^^^
cv-parser-worker-2  | TypeError: Client.__init__() got an unexpected keyword argument 'proxies'
cv-parser-worker-2  | {"timestamp": "2025-04-25 12:56:00,337", "level": "INFO", "logger": "root", "message": "Logging initialized", "pathname": "/app/app/core/logging.py", "lineno": 93, "process": 1, "thread": 281473538940960, "hostname": "fb7e8a7c05a6", "service": "cv-parser-service", "log_level": "INFO"}
cv-parser-worker-2  | {"timestamp": "2025-04-25 12:56:00,752", "level": "WARNING", "logger": "app.utils.validation", "message": "PyPDF2 non disponible, la validation des PDF sera limit\u00e9e", "pathname": "/app/app/utils/validation.py", "lineno": 31, "process": 1, "thread": 281473538940960, "hostname": "fb7e8a7c05a6", "service": "cv-parser-service"}
cv-parser-worker-2  | Traceback (most recent call last):
cv-parser-worker-2  |   File "/app/worker.py", line 11, in <module>
cv-parser-worker-2  |     from app.core.config import settings
cv-parser-worker-2  |   File "/app/app/__init__.py", line 34, in <module>
cv-parser-worker-2  |     from app.api.routes import router as api_router
cv-parser-worker-2  |   File "/app/app/api/routes.py", line 18, in <module>
cv-parser-worker-2  |     from app.workers.tasks import parse_cv_task
cv-parser-worker-2  |   File "/app/app/workers/tasks.py", line 14, in <module>
cv-parser-worker-2  |     from app.services.parser import parse_cv
cv-parser-worker-2  |   File "/app/app/services/parser.py", line 15, in <module>
cv-parser-worker-2  |     from app.services.resilience import resilient_openai_call
cv-parser-worker-2  |   File "/app/app/services/resilience.py", line 17, in <module>
cv-parser-worker-2  |     client = OpenAI(api_key=settings.OPENAI_API_KEY)
cv-parser-worker-2  |              ^^^^^^^^^^^^^^^^^^^^^^^^^^^^^^^^^^^^^^^
cv-parser-worker-2  |   File "/usr/local/lib/python3.11/site-packages/openai/_client.py", line 107, in __init__
cv-parser-worker-2  |     super().__init__(
cv-parser-worker-2  |   File "/usr/local/lib/python3.11/site-packages/openai/_base_client.py", line 738, in __init__
cv-parser-worker-2  |     self._client = http_client or httpx.Client(
cv-parser-worker-2  |                                   ^^^^^^^^^^^^^
cv-parser-worker-2  | TypeError: Client.__init__() got an unexpected keyword argument 'proxies'
cv-parser-worker-2  | {"timestamp": "2025-04-25 12:57:03,054", "level": "INFO", "logger": "root", "message": "Logging initialized", "pathname": "/app/app/core/logging.py", "lineno": 93, "process": 1, "thread": 281473595199520, "hostname": "fb7e8a7c05a6", "service": "cv-parser-service", "log_level": "INFO"}
cv-parser-worker-2  | {"timestamp": "2025-04-25 12:57:03,418", "level": "WARNING", "logger": "app.utils.validation", "message": "PyPDF2 non disponible, la validation des PDF sera limit\u00e9e", "pathname": "/app/app/utils/validation.py", "lineno": 31, "process": 1, "thread": 281473595199520, "hostname": "fb7e8a7c05a6", "service": "cv-parser-service"}
cv-parser-worker-2  | Traceback (most recent call last):
cv-parser-worker-2  |   File "/app/worker.py", line 11, in <module>
cv-parser-worker-2  |     from app.core.config import settings
cv-parser-worker-2  |   File "/app/app/__init__.py", line 34, in <module>
cv-parser-worker-2  |     from app.api.routes import router as api_router
cv-parser-worker-2  |   File "/app/app/api/routes.py", line 18, in <module>
cv-parser-worker-2  |     from app.workers.tasks import parse_cv_task
cv-parser-worker-2  |   File "/app/app/workers/tasks.py", line 14, in <module>
cv-parser-worker-2  |     from app.services.parser import parse_cv
cv-parser-worker-2  |   File "/app/app/services/parser.py", line 15, in <module>
cv-parser-worker-2  |     from app.services.resilience import resilient_openai_call
cv-parser-worker-2  |   File "/app/app/services/resilience.py", line 17, in <module>
cv-parser-worker-2  |     client = OpenAI(api_key=settings.OPENAI_API_KEY)
cv-parser-worker-1  |     from app.services.parser import parse_cv
cv-parser-worker-1  |   File "/app/app/services/parser.py", line 15, in <module>
cv-parser-worker-1  |     from app.services.resilience import resilient_openai_call
cv-parser-worker-1  |   File "/app/app/services/resilience.py", line 17, in <module>
cv-parser-worker-1  |     client = OpenAI(api_key=settings.OPENAI_API_KEY)
cv-parser-worker-1  |              ^^^^^^^^^^^^^^^^^^^^^^^^^^^^^^^^^^^^^^^
cv-parser-worker-1  |   File "/usr/local/lib/python3.11/site-packages/openai/_client.py", line 107, in __init__
cv-parser-worker-1  |     super().__init__(
cv-parser-worker-1  |   File "/usr/local/lib/python3.11/site-packages/openai/_base_client.py", line 738, in __init__
cv-parser-worker-1  |     self._client = http_client or httpx.Client(
cv-parser-worker-1  |                                   ^^^^^^^^^^^^^
cv-parser-worker-2  |              ^^^^^^^^^^^^^^^^^^^^^^^^^^^^^^^^^^^^^^^
cv-parser-worker-2  |   File "/usr/local/lib/python3.11/site-packages/openai/_client.py", line 107, in __init__
cv-parser-worker-2  |     super().__init__(
cv-parser-worker-2  |   File "/usr/local/lib/python3.11/site-packages/openai/_base_client.py", line 738, in __init__
cv-parser-worker-2  |     self._client = http_client or httpx.Client(
cv-parser-worker-2  |                                   ^^^^^^^^^^^^^
cv-parser-worker-2  | TypeError: Client.__init__() got an unexpected keyword argument 'proxies'
cv-parser-worker-2  | {"timestamp": "2025-04-25 12:58:05,606", "level": "INFO", "logger": "root", "message": "Logging initialized", "pathname": "/app/app/core/logging.py", "lineno": 93, "process": 1, "thread": 281472990810144, "hostname": "fb7e8a7c05a6", "service": "cv-parser-service", "log_level": "INFO"}
cv-parser-worker-2  | {"timestamp": "2025-04-25 12:58:06,077", "level": "WARNING", "logger": "app.utils.validation", "message": "PyPDF2 non disponible, la validation des PDF sera limit\u00e9e", "pathname": "/app/app/utils/validation.py", "lineno": 31, "process": 1, "thread": 281472990810144, "hostname": "fb7e8a7c05a6", "service": "cv-parser-service"}
cv-parser-worker-2  | Traceback (most recent call last):
cv-parser-worker-2  |   File "/app/worker.py", line 11, in <module>
cv-parser-worker-2  |     from app.core.config import settings
cv-parser-worker-2  |   File "/app/app/__init__.py", line 34, in <module>
cv-parser-worker-2  |     from app.api.routes import router as api_router
cv-parser-worker-2  |   File "/app/app/api/routes.py", line 18, in <module>
cv-parser-worker-2  |     from app.workers.tasks import parse_cv_task
cv-parser-worker-2  |   File "/app/app/workers/tasks.py", line 14, in <module>
cv-parser-worker-2  |     from app.services.parser import parse_cv
cv-parser-worker-2  |   File "/app/app/services/parser.py", line 15, in <module>
cv-parser-worker-2  |     from app.services.resilience import resilient_openai_call
cv-parser-worker-2  |   File "/app/app/services/resilience.py", line 17, in <module>
cv-parser-worker-1  | TypeError: Client.__init__() got an unexpected keyword argument 'proxies'
cv-parser-worker-1  | {"timestamp": "2025-04-25 12:56:00,365", "level": "INFO", "logger": "root", "message": "Logging initialized", "pathname": "/app/app/core/logging.py", "lineno": 93, "process": 1, "thread": 281473055207456, "hostname": "aa5e390c721e", "service": "cv-parser-service", "log_level": "INFO"}
cv-parser-worker-1  | {"timestamp": "2025-04-25 12:56:00,755", "level": "WARNING", "logger": "app.utils.validation", "message": "PyPDF2 non disponible, la validation des PDF sera limit\u00e9e", "pathname": "/app/app/utils/validation.py", "lineno": 31, "process": 1, "thread": 281473055207456, "hostname": "aa5e390c721e", "service": "cv-parser-service"}
cv-parser-worker-1  | Traceback (most recent call last):
cv-parser-worker-1  |   File "/app/worker.py", line 11, in <module>
cv-parser-worker-1  |     from app.core.config import settings
cv-parser-worker-1  |   File "/app/app/__init__.py", line 34, in <module>
cv-parser-worker-1  |     from app.api.routes import router as api_router
cv-parser-worker-1  |   File "/app/app/api/routes.py", line 18, in <module>
cv-parser-worker-1  |     from app.workers.tasks import parse_cv_task
cv-parser-worker-1  |   File "/app/app/workers/tasks.py", line 14, in <module>
cv-parser-worker-1  |     from app.services.parser import parse_cv
cv-parser-worker-1  |   File "/app/app/services/parser.py", line 15, in <module>
cv-parser-worker-1  |     from app.services.resilience import resilient_openai_call
cv-parser-worker-1  |   File "/app/app/services/resilience.py", line 17, in <module>
cv-parser-worker-1  |     client = OpenAI(api_key=settings.OPENAI_API_KEY)
cv-parser-worker-1  |              ^^^^^^^^^^^^^^^^^^^^^^^^^^^^^^^^^^^^^^^
cv-parser-worker-2  |     client = OpenAI(api_key=settings.OPENAI_API_KEY)
cv-parser-worker-2  |              ^^^^^^^^^^^^^^^^^^^^^^^^^^^^^^^^^^^^^^^
cv-parser-worker-2  |   File "/usr/local/lib/python3.11/site-packages/openai/_client.py", line 107, in __init__
cv-parser-worker-2  |     super().__init__(
cv-parser-worker-2  |   File "/usr/local/lib/python3.11/site-packages/openai/_base_client.py", line 738, in __init__
cv-parser-worker-2  |     self._client = http_client or httpx.Client(
cv-parser-worker-2  |                                   ^^^^^^^^^^^^^
cv-parser-worker-2  | TypeError: Client.__init__() got an unexpected keyword argument 'proxies'
cv-parser-worker-2  | {"timestamp": "2025-04-25 12:59:08,196", "level": "INFO", "logger": "root", "message": "Logging initialized", "pathname": "/app/app/core/logging.py", "lineno": 93, "process": 1, "thread": 281473304285216, "hostname": "fb7e8a7c05a6", "service": "cv-parser-service", "log_level": "INFO"}
cv-parser-worker-2  | {"timestamp": "2025-04-25 12:59:08,485", "level": "WARNING", "logger": "app.utils.validation", "message": "PyPDF2 non disponible, la validation des PDF sera limit\u00e9e", "pathname": "/app/app/utils/validation.py", "lineno": 31, "process": 1, "thread": 281473304285216, "hostname": "fb7e8a7c05a6", "service": "cv-parser-service"}
cv-parser-worker-2  | Traceback (most recent call last):
cv-parser-worker-2  |   File "/app/worker.py", line 11, in <module>
cv-parser-worker-2  |     from app.core.config import settings
cv-parser-worker-2  |   File "/app/app/__init__.py", line 34, in <module>
cv-parser-worker-2  |     from app.api.routes import router as api_router
cv-parser-worker-2  |   File "/app/app/api/routes.py", line 18, in <module>
cv-parser-worker-2  |     from app.workers.tasks import parse_cv_task
cv-parser-worker-2  |   File "/app/app/workers/tasks.py", line 14, in <module>
cv-parser-worker-2  |     from app.services.parser import parse_cv
cv-parser-worker-2  |   File "/app/app/services/parser.py", line 15, in <module>
cv-parser-worker-2  |     from app.services.resilience import resilient_openai_call
cv-parser-worker-2  |   File "/app/app/services/resilience.py", line 17, in <module>
cv-parser-worker-1  |   File "/usr/local/lib/python3.11/site-packages/openai/_client.py", line 107, in __init__
cv-parser-worker-1  |     super().__init__(
cv-parser-worker-1  |   File "/usr/local/lib/python3.11/site-packages/openai/_base_client.py", line 738, in __init__
cv-parser-worker-1  |     self._client = http_client or httpx.Client(
cv-parser-worker-2  |     client = OpenAI(api_key=settings.OPENAI_API_KEY)
cv-parser-worker-2  |              ^^^^^^^^^^^^^^^^^^^^^^^^^^^^^^^^^^^^^^^
cv-parser-worker-2  |   File "/usr/local/lib/python3.11/site-packages/openai/_client.py", line 107, in __init__
cv-parser-worker-2  |     super().__init__(
cv-parser-worker-2  |   File "/usr/local/lib/python3.11/site-packages/openai/_base_client.py", line 738, in __init__
cv-parser-worker-1  |                                   ^^^^^^^^^^^^^
cv-parser-worker-1  | TypeError: Client.__init__() got an unexpected keyword argument 'proxies'
cv-parser-worker-1  | {"timestamp": "2025-04-25 12:57:03,051", "level": "INFO", "logger": "root", "message": "Logging initialized", "pathname": "/app/app/core/logging.py", "lineno": 93, "process": 1, "thread": 281472955863072, "hostname": "aa5e390c721e", "service": "cv-parser-service", "log_level": "INFO"}
cv-parser-worker-1  | {"timestamp": "2025-04-25 12:57:03,418", "level": "WARNING", "logger": "app.utils.validation", "message": "PyPDF2 non disponible, la validation des PDF sera limit\u00e9e", "pathname": "/app/app/utils/validation.py", "lineno": 31, "process": 1, "thread": 281472955863072, "hostname": "aa5e390c721e", "service": "cv-parser-service"}
cv-parser-worker-1  | Traceback (most recent call last):
cv-parser-worker-1  |   File "/app/worker.py", line 11, in <module>
cv-parser-worker-1  |     from app.core.config import settings
cv-parser-worker-1  |   File "/app/app/__init__.py", line 34, in <module>
cv-parser-worker-1  |     from app.api.routes import router as api_router
cv-parser-worker-1  |   File "/app/app/api/routes.py", line 18, in <module>
cv-parser-worker-1  |     from app.workers.tasks import parse_cv_task
cv-parser-worker-2  |     self._client = http_client or httpx.Client(
cv-parser-worker-2  |                                   ^^^^^^^^^^^^^
cv-parser-worker-2  | TypeError: Client.__init__() got an unexpected keyword argument 'proxies'
cv-parser-worker-1  |   File "/app/app/workers/tasks.py", line 14, in <module>
cv-parser-worker-1  |     from app.services.parser import parse_cv
cv-parser-worker-1  |   File "/app/app/services/parser.py", line 15, in <module>
cv-parser-worker-1  |     from app.services.resilience import resilient_openai_call
cv-parser-worker-1  |   File "/app/app/services/resilience.py", line 17, in <module>
cv-parser-worker-1  |     client = OpenAI(api_key=settings.OPENAI_API_KEY)
cv-parser-worker-1  |              ^^^^^^^^^^^^^^^^^^^^^^^^^^^^^^^^^^^^^^^
cv-parser-worker-1  |   File "/usr/local/lib/python3.11/site-packages/openai/_client.py", line 107, in __init__
cv-parser-worker-1  |     super().__init__(
cv-parser-worker-1  |   File "/usr/local/lib/python3.11/site-packages/openai/_base_client.py", line 738, in __init__
cv-parser-worker-1  |     self._client = http_client or httpx.Client(
cv-parser-worker-1  |                                   ^^^^^^^^^^^^^
cv-parser-worker-1  | TypeError: Client.__init__() got an unexpected keyword argument 'proxies'
cv-parser-worker-1  | {"timestamp": "2025-04-25 12:58:05,661", "level": "INFO", "logger": "root", "message": "Logging initialized", "pathname": "/app/app/core/logging.py", "lineno": 93, "process": 1, "thread": 281472963178528, "hostname": "aa5e390c721e", "service": "cv-parser-service", "log_level": "INFO"}
cv-parser-worker-1  | {"timestamp": "2025-04-25 12:58:06,048", "level": "WARNING", "logger": "app.utils.validation", "message": "PyPDF2 non disponible, la validation des PDF sera limit\u00e9e", "pathname": "/app/app/utils/validation.py", "lineno": 31, "process": 1, "thread": 281472963178528, "hostname": "aa5e390c721e", "service": "cv-parser-service"}
cv-parser-worker-1  | Traceback (most recent call last):
cv-parser-worker-1  |   File "/app/worker.py", line 11, in <module>
cv-parser-worker-1  |     from app.core.config import settings
cv-parser-worker-1  |   File "/app/app/__init__.py", line 34, in <module>
cv-parser-worker-1  |     from app.api.routes import router as api_router
cv-parser-worker-1  |   File "/app/app/api/routes.py", line 18, in <module>
cv-parser-worker-1  |     from app.workers.tasks import parse_cv_task
cv-parser-worker-1  |   File "/app/app/workers/tasks.py", line 14, in <module>
cv-parser-worker-1  |     from app.services.parser import parse_cv
cv-parser-worker-1  |   File "/app/app/services/parser.py", line 15, in <module>
cv-parser-worker-1  |     from app.services.resilience import resilient_openai_call
cv-parser-worker-1  |   File "/app/app/services/resilience.py", line 17, in <module>
cv-parser-worker-1  |     client = OpenAI(api_key=settings.OPENAI_API_KEY)
cv-parser-worker-1  |              ^^^^^^^^^^^^^^^^^^^^^^^^^^^^^^^^^^^^^^^
cv-parser-worker-1  |   File "/usr/local/lib/python3.11/site-packages/openai/_client.py", line 107, in __init__
cv-parser-worker-1  |     super().__init__(
cv-parser-worker-1  |   File "/usr/local/lib/python3.11/site-packages/openai/_base_client.py", line 738, in __init__
cv-parser-worker-1  |     self._client = http_client or httpx.Client(
cv-parser-worker-1  |                                   ^^^^^^^^^^^^^
cv-parser-worker-1  | TypeError: Client.__init__() got an unexpected keyword argument 'proxies'
cv-parser-worker-1  | {"timestamp": "2025-04-25 12:59:07,977", "level": "INFO", "logger": "root", "message": "Logging initialized", "pathname": "/app/app/core/logging.py", "lineno": 93, "process": 1, "thread": 281473675444256, "hostname": "aa5e390c721e", "service": "cv-parser-service", "log_level": "INFO"}
cv-parser-worker-1  | {"timestamp": "2025-04-25 12:59:08,369", "level": "WARNING", "logger": "app.utils.validation", "message": "PyPDF2 non disponible, la validation des PDF sera limit\u00e9e", "pathname": "/app/app/utils/validation.py", "lineno": 31, "process": 1, "thread": 281473675444256, "hostname": "aa5e390c721e", "service": "cv-parser-service"}
cv-parser-worker-1  | Traceback (most recent call last):
cv-parser-worker-1  |   File "/app/worker.py", line 11, in <module>
cv-parser-worker-1  |     from app.core.config import settings
cv-parser-worker-1  |   File "/app/app/__init__.py", line 34, in <module>
cv-parser-worker-1  |     from app.api.routes import router as api_router
cv-parser-worker-1  |   File "/app/app/api/routes.py", line 18, in <module>
cv-parser-worker-1  |     from app.workers.tasks import parse_cv_task
cv-parser-worker-1  |   File "/app/app/workers/tasks.py", line 14, in <module>
cv-parser-worker-1  |     from app.services.parser import parse_cv
cv-parser-worker-1  |   File "/app/app/services/parser.py", line 15, in <module>
cv-parser-worker-1  |     from app.services.resilience import resilient_openai_call
cv-parser-worker-1  |   File "/app/app/services/resilience.py", line 17, in <module>
cv-parser-worker-1  |     client = OpenAI(api_key=settings.OPENAI_API_KEY)
cv-parser-worker-1  |              ^^^^^^^^^^^^^^^^^^^^^^^^^^^^^^^^^^^^^^^
cv-parser-worker-1  |   File "/usr/local/lib/python3.11/site-packages/openai/_client.py", line 107, in __init__
cv-parser-worker-1  |     super().__init__(
cv-parser-worker-1  |   File "/usr/local/lib/python3.11/site-packages/openai/_base_client.py", line 738, in __init__
cv-parser-worker-1  |     self._client = http_client or httpx.Client(
cv-parser-worker-1  |                                   ^^^^^^^^^^^^^
cv-parser-worker-1  | TypeError: Client.__init__() got an unexpected keyword argument 'proxies'
